Workbook

Sheet Datos_Originales
A1: Fecha de venta | B1: Ciudad | C1: Producto | D1: Precio unitario | E1: Cantidad | F1: Monto total | G1: Cliente | H1: Email | I1: ID de orden
A2: 45566 | B2: monterrey | C2: Tablet-Estándar-8GB | D2: 1339.17 | E2: 2 | F2: 2678.34 | G2: Rebeca Salvador Gamez García | H2: qcovarrubias@hotmail.com | I2: 53a9e98d-d57a-488e-bcec-701bc4e1ec3e
A3: 45566 | B3: bogotá | C3: Auriculares-Con cable-32GB | D3: 716.29 | E3: 1 | F3: 716.29 | G3: Evelio Ramiro Arce | H3: gaytansergio@navarro.info | I3: 10c739f0-f7fb-4c8e-a239-ed1f5c295465
A4: 45568 | B4: monterrey | C4: Auriculares-Con cable-32GB | D4: 439.01 | E4: 5 | F4: 2195.05 | G4: Sandra Baez | H4: maria-teresamanzanares@jaquez.com | I4: d7c9e19e-1228-4326-8b2a-cde42e222a67
A5: 45568 | B5: bogotá | C5: Tablet-Estándar-16GB | D5: 741.79 | E5: 2 | F5: 1483.58 | G5: Uriel Helena Caldera | H5: pizarrojaqueline@acuna-moreno.com | I5: 91de2837-a873-4607-8185-7fa6844d2be8
A6: 45568 | B6: bogotá | C6: Tablet-Estándar-8GB | D6: 984.34 | E6: 3 | F6: 2953.02 | G6: Wendolin Jeronimo Farías | H6: yterrazas@hotmail.com | I6: 4cfd7c38-6607-4b36-ab60-fb259d4e18b4
A7: 45568 | B7: Ciudad de Mexico | C7: Teléfono-Gama alta-32GB | D7: 2419.81 | E7: 5 | F7: 12099.05 | G7: Esteban Ureña | H7: gvazquez@burgos.com | I7: a4da2665-dfb9-46f3-b658-cc5d0505dd86
A8: 45568 | B8: Medellín | C8: Tablet-Pro-4GB | D8: 145.9 | E8: 5 | F8: 729.5 | G8: Aida Ojeda Galindo | H8: concepcion88@hotmail.com | I8: 8d23f99e-11a9-4194-979d-e2f334eec6fa
A9: 45569 | B9: Ciudad de Mexico | C9: Auriculares-Con cable-8GB | D9: 1086.48 | E9: 1 | F9: 1086.48 | G9: Cristal Luis Manuel Sanchez | H9: rocioescalante@hotmail.com | I9: a895a20b-523d-4f9e-a3e5-039259362c4f
A10: 45570 | B10: monterrey | C10: Auriculares-Con cable-8GB | D10: 1898.32 | E10: 4 | F10: 7593.28 | G10: Daniela Padron | H10: dromero@industrias.info | I10: 14722e2a-7971-43ee-ac45-587157e6f198
A11: 45571 | B11: monterrey | C11: Tablet-Estándar-8GB | D11: 1280.61 | E11: 5 | F11: 6403.05 | G11: Lic. Elena Zepeda | H11: emiliovillegas@diaz-ulibarri.net | I11: 7424e9fb-eb47-4eb6-b0ee-330eb470b214
A12: 45571 | B12: Medellín | C12: Tablet-Estándar-32GB | D12: 1753 | E12: 5 | F12: 8765 | G12: Cristal Rincon | H12: maria-teresaibarra@yahoo.com | I12: a4b8a935-59ba-43d2-9d68-660ee91a5acd
A13: 45572 | B13: Ciudad de Mexico | C13: Laptop-Oficina-8GB | D13: 370.25 | E13: 4 | F13: 1481 | G13: Francisca Lucas Jaimes Zavala | H13: baezjonas@proyectos.org | I13: 9c8710a3-d9ef-4a00-9c0b-7c93d5fb8f63
... A48: 45578 | B48: Guadalajara | C48: Auriculares-Cancelaci√≥n de ruido-16GB | D48: 284.79 | E48: 5 | F48: 1423.95 | G48: Alta Gracia Alicia Guzman | H48: rosasgabriela@gmail.com | I48: 88268205-0f39-4e9a-9353-1a9ee68c009c
A49: 45578 | B49: monterrey | C49: Laptop-Ultraliviana-16GB | E49: 3 | F49: 1086.51 | G49: Rodrigo Vanegas Serna | H49: vicentezelaya@valdez.com | I49: 426433ea-0410-4d24-b435-247c7b633415
A50: 45578 | B50: Guadalajara | C50: Laptop-Oficina-8GB | D50: 1274.8 | E50: 5 | F50: 6374 | G50: Luis Camila Guardado | H50: deborallamas@hotmail.com | I50: dca19bf4-3f5f-484c-bfdb-75c9ded28858
A51: 45578 | B51: Guadalajara | C51: Tablet-Pro-4GB | D51: 233.85 | E51: 4 | F51: 935.4 | G51: Mtro. Rafaél Najera | H51: fernando51@yahoo.com | I51: 7594ffab-c88c-40b4-b851-6897e6230fb0
A52: 45578 | B52: Ciudad de Mexico | C52: Auriculares-Con cable-32GB | D52: 142.14 | E52: 3 | F52: 426.42 | G52: Clemente Lucas de la Crúz Florez | H52: miriam03@laboratorios.com | I52: 306238f0-70d8-49c3-bc3f-5c9df03698bf
A53: 45578 | B53: Medellín | C53: Teléfono-Gama alta-8GB | D53: 226.52 | E53: 2 | F53: 453.04 | G53: Ing. Cecilia Gurule | H53: pulidoindira@industrias.org | I53: 13857721-e31a-444e-a2c2-774566eb5f26
A54: 45578 | B54: Ciudad de Mexico | C54: Tablet-Mini-32GB | D54: 1922.79 | E54: 3 | F54: 5768.37 | G54: Elias Juan Carlos Estévez Cepeda | H54: virginiameraz@yahoo.com | I54: a2d32009-f750-4260-8311-8300bd425ff8
A55: 45578 | B55: bogotá | C55: Tablet-Pro-8GB | E55: 2 | F55: 4429.96 | G55: Alta Gracia Marrero Ocasio | H55: leonardorosas@laboratorios.com | I55: fad038ce-1b32-4c25-85bc-38c2262677ee
A56: 45579 | B56: bogotá | C56: Laptop-Ultraliviana-16GB | D56: 120.94 | E56: 3 | G56: Esmeralda Bañuelos | H56: gdel-rio@proyectos.biz | I56: 4a70ae74-59ef-4f8f-98ee-d8fff858e22d
A57: 45579 | B57: Medellín | C57: Tablet-Mini-8GB | D57: 1950.45 | E57: 4 | F57: 7801.8 | G57: Angélica Bueno Olvera | H57: bernabe37@despacho.com | I57: 9ffc235a-1e2b-44c3-80ec-61b7a7d4cbc5
A58: 45579 | B58: bogotá | C58: Teléfono-Gama media-4GB | D58: 2092.55 | E58: 5 | F58: 10462.75 | G58: Roberto Casarez Lozada | H58: granadosaraceli@proyectos.net | I58: 890c4fe3-a2aa-473b-a2ff-9c2704d3ac14
A59: 45579 | B59: Medellín | C59: Tablet-Estándar-8GB | D59: 214.72 | E59: 3 | F59: 644.16 | G59: Dr. Pedro Zapata | H59: ursulamenchaca@hotmail.com | I59: 7413d048-5e1b-4043-9969-89781ce744b0
A60: 45579 | B60: Guadalajara | C60: Laptop-Gaming-16GB | D60: 1291.39 | E60: 3 | F60: 3874.17 | G60: Mtro. Salma de la Garza | H60: ana-luisa49@otero.org | I60: 40b3bbac-c623-4647-a606-b5af9a39c69f
A61: 45579 | B61: Ciudad de Mexico | C61: Laptop-Oficina-4GB | D61: 970.38 | E61: 5 | F61: 4851.9 | G61: Tania Soto Nieves | H61: jeronimovigil@hotmail.com | I61: af87cfff-afb0-4f85-888d-e5db29ae4766
A62: 45579 | B62: CALI | C62: Tablet-Mini-16GB | D62: 2101.48 | E62: 2 | F62: 4202.96 | G62: Leticia Luevano Mayorga | H62: orascon@corporacin.com | I62: f0548b33-86eb-4b3f-a1f4-cef9f9f11955
A63: 45579 | B63: bogotá | C63: Laptop-Ultraliviana-4GB | D63: 302.84 | E63: 3 | F63: 908.52 | G63: Lic. Leonel Orosco | H63: dponce@verdugo.info | I63: 972dd545-20a8-49a2-be8a-93f570eba58b
A64: 45579 | B64: monterrey | C64: Auriculares-Con cable-32GB | D64: 1421.57 | E64: 4 | F64: 5686.28 | G64: Hernan Anguiano | H64: adriana27@hotmail.com | I64: 6b47665a-5972-4a11-a9e7-d42e56cf42a4
A65: 45579 | B65: monterrey | C65: Tablet-Mini-8GB | D65: 1037.64 | E65: 3 | F65: 3112.92 | G65: Dr. Yolanda Miranda | H65: oswaldo20@proyectos.net | I65: 8e55023b-2774-4015-86a2-780e882c0d87
A66: 45579 | B66: monterrey | C66: Auriculares-Con cable-16GB | D66: 579.54 | E66: 3 | F66: 1738.62 | G66: Ing. Judith Ayala | H66: paolavergara@laboratorios.net | I66: 64e8cb7b-f59e-470c-b704-3f79a8f2cc9e
A67: 45579 | B67: Medellín | C67: Tablet-Mini-4GB | D67: 796.49 | E67: 3 | F67: 2389.47 | G67: Carmen Rufino Téllez Benavides | H67: leonortoledo@solorzano.com | I67: dac843fc-5bc0-475f-a01e-8c48a965a9c2
A68: 45579 | B68: bogotá | C68: Tel√©fono-Gama media-8GB | D68: 1838.04 | E68: 4 | F68: 7352.16 | G68: Wendolin Fonseca | H68: linda23@gmail.com | I68: fc8a05ee-e84e-44f7-96be-898033a352b4
... A91: 45581 | B91: CALI | C91: Teléfono-Gama baja-16GB | D91: 833.39 | E91: 1 | F91: 833.39 | G91: Mtro. Estela Villanueva | H91: salma61@gmail.com | I91: 8cbf9f9b-f7d4-44ca-9484-0940e88fe51a
A92: 45581 | B92: bogotá | C92: Teléfono-Gama media-4GB | E92: 5 | F92: 11708.85 | G92: Enrique Crespo Alvarez | H92: pamela41@grupo.com | I92: 6321df0f-9103-4ad4-8571-120df4dd675b
A93: 45581 | B93: Medellín | C93: Auriculares-Bluetooth-32GB | D93: 397.5 | E93: 2 | F93: 795 | G93: Víctor Jaramillo | H93: vallejogustavo@despacho.net | I93: cb4fece9-bf8f-4e7d-8218-b9d826729e46
A94: 45581 | B94: Ciudad de Mexico | C94: Laptop-Gaming-32GB | D94: 100.75 | E94: 1 | F94: 100.75 | G94: Asuncion Badillo | H94: carlota45@yahoo.com | I94: a279348c-c747-4e18-b056-f066a8c54d22
A95: 45581 | B95: Ciudad de Mexico | C95: Teléfono-Gama baja-32GB | D95: 1268.91 | E95: 2 | F95: 2537.82 | G95: Rosalia Florencia Contreras | H95: olverapamela@yahoo.com | I95: 54ac59d8-1eda-4373-bd55-691a4a1a13f9
A96: 45581 | B96: Ciudad de Mexico | C96: Laptop-Ultraliviana-8GB | D96: 903.41 | E96: 3 | F96: 2710.23 | G96: Diego Armando Portillo | H96: rociopalomino@valenzuela.com | I96: 278f1d63-6044-406a-b286-8ed51ce0b45a
...

Sheet Datos_Limpios
A1: Fecha de venta | B1: Mes | C1: Ciudad | D1: Ciudad Corregida | E1: Producto | F1: Categoria | G1: Tipo | H1: Especificaciones | I1: Precio unitario | J1: Cantidad | K1: Monto total | L1: Cliente | M1: Email | N1: ID de orden
A2: 45566 | B2: =TEXT(A2,"mmmm") -> October | C2: monterrey | D2: =PROPER(TRIM(C2)) -> Monterrey | E2: Tablet-Estándar-8GB | F2: =IFERROR(__xludf.DUMMYFUNCTION("SPLIT(E2, ""-"")"),"Tablet") -> Tablet | G2: =IFERROR(__xludf.DUMMYFUNCTION("""COMPUTED_VALUE"""),"Estándar") -> Estándar | H2: =IFERROR(__xludf.DUMMYFUNCTION("""COMPUTED_VALUE"""),"8GB") -> 8GB | I2: 1339.17 | J2: 2 | K2: 2678.34 | L2: Rebeca Salvador Gamez García | M2: qcovarrubias@hotmail.com | N2: 53a9e98d-d57a-488e-bcec-701bc4e1ec3e
A3: 45566 | B3: =TEXT(A3,"mmmm") -> October | C3: bogotá | D3: =PROPER(TRIM(C3)) -> Bogotá | E3: Auriculares-Con cable-32GB | F3: =IFERROR(__xludf.DUMMYFUNCTION("SPLIT(E3, ""-"")"),"Auriculares") -> Auriculares | G3: =IFERROR(__xludf.DUMMYFUNCTION("""COMPUTED_VALUE"""),"Con cable") -> Con cable | H3: =IFERROR(__xludf.DUMMYFUNCTION("""COMPUTED_VALUE"""),"32GB") -> 32GB | I3: 716.29 | J3: 1 | K3: 716.29 | L3: Evelio Ramiro Arce | M3: gaytansergio@navarro.info | N3: 10c739f0-f7fb-4c8e-a239-ed1f5c295465
A4: 45568 | B4: =TEXT(A4,"mmmm") -> October | C4: monterrey | D4: =PROPER(TRIM(C4)) -> Monterrey | E4: Auriculares-Con cable-32GB | F4: =IFERROR(__xludf.DUMMYFUNCTION("SPLIT(E4, ""-"")"),"Auriculares") -> Auriculares | G4: =IFERROR(__xludf.DUMMYFUNCTION("""COMPUTED_VALUE"""),"Con cable") -> Con cable | H4: =IFERROR(__xludf.DUMMYFUNCTION("""COMPUTED_VALUE"""),"32GB") -> 32GB | I4: 439.01 | J4: 5 | K4: 2195.05 | L4: Sandra Baez | M4: maria-teresamanzanares@jaquez.com | N4: d7c9e19e-1228-4326-8b2a-cde42e222a67
A5: 45568 | B5: =TEXT(A5,"mmmm") -> October | C5: bogotá | D5: =PROPER(TRIM(C5)) -> Bogotá | E5: Tablet-Estándar-16GB | F5: =IFERROR(__xludf.DUMMYFUNCTION("SPLIT(E5, ""-"")"),"Tablet") -> Tablet | G5: =IFERROR(__xludf.DUMMYFUNCTION("""COMPUTED_VALUE"""),"Estándar") -> Estándar | H5: =IFERROR(__xludf.DUMMYFUNCTION("""COMPUTED_VALUE"""),"16GB") -> 16GB | I5: 741.79 | J5: 2 | K5: 1483.58 | L5: Uriel Helena Caldera | M5: pizarrojaqueline@acuna-moreno.com | N5: 91de2837-a873-4607-8185-7fa6844d2be8
A6: 45568 | B6: =TEXT(A6,"mmmm") -> October | C6: bogotá | D6: =PROPER(TRIM(C6)) -> Bogotá | E6: Tablet-Estándar-8GB | F6: =IFERROR(__xludf.DUMMYFUNCTION("SPLIT(E6, ""-"")"),"Tablet") -> Tablet | G6: =IFERROR(__xludf.DUMMYFUNCTION("""COMPUTED_VALUE"""),"Estándar") -> Estándar | H6: =IFERROR(__xludf.DUMMYFUNCTION("""COMPUTED_VALUE"""),"8GB") -> 8GB | I6: 984.34 | J6: 3 | K6: 2953.02 | L6: Wendolin Jeronimo Farías | M6: yterrazas@hotmail.com | N6: 4cfd7c38-6607-4b36-ab60-fb259d4e18b4
A7: 45568 | B7: =TEXT(A7,"mmmm") -> October | C7: Ciudad de Mexico | D7: =PROPER(TRIM(C7)) -> Ciudad De Mexico | E7: Teléfono-Gama alta-32GB | F7: =IFERROR(__xludf.DUMMYFUNCTION("SPLIT(E7, ""-"")"),"Teléfono") -> Teléfono | G7: =IFERROR(__xludf.DUMMYFUNCTION("""COMPUTED_VALUE"""),"Gama alta") -> Gama alta | H7: =IFERROR(__xludf.DUMMYFUNCTION("""COMPUTED_VALUE"""),"32GB") -> 32GB | I7: 2419.81 | J7: 5 | K7: 12099.05 | L7: Esteban Ureña | M7: gvazquez@burgos.com | N7: a4da2665-dfb9-46f3-b658-cc5d0505dd86
A8: 45568 | B8: =TEXT(A8,"mmmm") -> October | C8: Medellín | D8: =PROPER(TRIM(C8)) -> Medellín | E8: Tablet-Pro-4GB | F8: =IFERROR(__xludf.DUMMYFUNCTION("SPLIT(E8, ""-"")"),"Tablet") -> Tablet | G8: =IFERROR(__xludf.DUMMYFUNCTION("""COMPUTED_VALUE"""),"Pro") -> Pro | H8: =IFERROR(__xludf.DUMMYFUNCTION("""COMPUTED_VALUE"""),"4GB") -> 4GB | I8: 145.9 | J8: 5 | K8: 729.5 | L8: Aida Ojeda Galindo | M8: concepcion88@hotmail.com | N8: 8d23f99e-11a9-4194-979d-e2f334eec6fa
A9: 45569 | B9: =TEXT(A9,"mmmm") -> October | C9: Ciudad de Mexico | D9: =PROPER(TRIM(C9)) -> Ciudad De Mexico | E9: Auriculares-Con cable-8GB | F9: =IFERROR(__xludf.DUMMYFUNCTION("SPLIT(E9, ""-"")"),"Auriculares") -> Auriculares | G9: =IFERROR(__xludf.DUMMYFUNCTION("""COMPUTED_VALUE"""),"Con cable") -> Con cable | H9: =IFERROR(__xludf.DUMMYFUNCTION("""COMPUTED_VALUE"""),"8GB") -> 8GB | I9: 1086.48 | J9: 1 | K9: 1086.48 | L9: Cristal Luis Manuel Sanchez | M9: rocioescalante@hotmail.com | N9: a895a20b-523d-4f9e-a3e5-039259362c4f
A10: 45570 | B10: =TEXT(A10,"mmmm") -> October | C10: monterrey | D10: =PROPER(TRIM(C10)) -> Monterrey | E10: Auriculares-Con cable-8GB | F10: =IFERROR(__xludf.DUMMYFUNCTION("SPLIT(E10, ""-"")"),"Auriculares") -> Auriculares | G10: =IFERROR(__xludf.DUMMYFUNCTION("""COMPUTED_VALUE"""),"Con cable") -> Con cable | H10: =IFERROR(__xludf.DUMMYFUNCTION("""COMPUTED_VALUE"""),"8GB") -> 8GB | I10: 1898.32 | J10: 4 | K10: 7593.28 | L10: Daniela Padron | M10: dromero@industrias.info | N10: 14722e2a-7971-43ee-ac45-587157e6f198
A11: 45571 | B11: =TEXT(A11,"mmmm") -> October | C11: monterrey | D11: =PROPER(TRIM(C11)) -> Monterrey | E11: Tablet-Estándar-8GB | F11: =IFERROR(__xludf.DUMMYFUNCTION("SPLIT(E11, ""-"")"),"Tablet") -> Tablet | G11: =IFERROR(__xludf.DUMMYFUNCTION("""COMPUTED_VALUE"""),"Estándar") -> Estándar | H11: =IFERROR(__xludf.DUMMYFUNCTION("""COMPUTED_VALUE"""),"8GB") -> 8GB | I11: 1280.61 | J11: 5 | K11: 6403.05 | L11: Lic. Elena Zepeda | M11: emiliovillegas@diaz-ulibarri.net | N11: 7424e9fb-eb47-4eb6-b0ee-330eb470b214
A12: 45571 | B12: =TEXT(A12,"mmmm") -> October | C12: Medellín | D12: =PROPER(TRIM(C12)) -> Medellín | E12: Tablet-Estándar-32GB | F12: =IFERROR(__xludf.DUMMYFUNCTION("SPLIT(E12, ""-"")"),"Tablet") -> Tablet | G12: =IFERROR(__xludf.DUMMYFUNCTION("""COMPUTED_VALUE"""),"Estándar") -> Estándar | H12: =IFERROR(__xludf.DUMMYFUNCTION("""COMPUTED_VALUE"""),"32GB") -> 32GB | I12: 1753 | J12: 5 | K12: 8765 | L12: Cristal Rincon | M12: maria-teresaibarra@yahoo.com | N12: a4b8a935-59ba-43d2-9d68-660ee91a5acd
A13: 45572 | B13: =TEXT(A13,"mmmm") -> October | C13: Ciudad de Mexico | D13: =PROPER(TRIM(C13)) -> Ciudad De Mexico | E13: Laptop-Oficina-8GB | F13: =IFERROR(__xludf.DUMMYFUNCTION("SPLIT(E13, ""-"")"),"Laptop") -> Laptop | G13: =IFERROR(__xludf.DUMMYFUNCTION("""COMPUTED_VALUE"""),"Oficina") -> Oficina | H13: =IFERROR(__xludf.DUMMYFUNCTION("""COMPUTED_VALUE"""),"8GB") -> 8GB | I13: 370.25 | J13: 4 | K13: 1481 | L13: Francisca Lucas Jaimes Zavala | M13: baezjonas@proyectos.org | N13: 9c8710a3-d9ef-4a00-9c0b-7c93d5fb8f63
A14: 45572 | B14: =TEXT(A14,"mmmm") -> October | C14: Guadalajara | D14: =PROPER(TRIM(C14)) -> Guadalajara | E14: Auriculares-Bluetooth-4GB | F14: =IFERROR(__xludf.DUMMYFUNCTION("SPLIT(E14, ""-"")"),"Auriculares") -> Auriculares | G14: =IFERROR(__xludf.DUMMYFUNCTION("""COMPUTED_VALUE"""),"Bluetooth") -> Bluetooth | H14: =IFERROR(__xludf.DUMMYFUNCTION("""COMPUTED_VALUE"""),"4GB") -> 4GB | I14: 62.73 | J14: 3 | K14: 188.19 | L14: Elisa Soria | M14: guillerminacorral@yahoo.com | N14: eb72415a-2fdb-436d-a740-aa38fe92dba8
A15: 45573 | B15: =TEXT(A15,"mmmm") -> October | C15: Medellín | D15: =PROPER(TRIM(C15)) -> Medellín | E15: Laptop-Ultraliviana-4GB | F15: =IFERROR(__xludf.DUMMYFUNCTION("SPLIT(E15, ""-"")"),"Laptop") -> Laptop | G15: =IFERROR(__xludf.DUMMYFUNCTION("""COMPUTED_VALUE"""),"Ultraliviana") -> Ultraliviana | H15: =IFERROR(__xludf.DUMMYFUNCTION("""COMPUTED_VALUE"""),"4GB") -> 4GB | I15: 2314.37 | J15: 5 | K15: 11571.85 | L15: Rosalia Alcantar | M15: luisamata@barajas-de.org | N15: a9fee7b5-3729-4db8-815f-355ff6236823
A16: 45573 | B16: =TEXT(A16,"mmmm") -> October | C16: Medellín | D16: =PROPER(TRIM(C16)) -> Medellín | E16: Tablet-Estándar-4GB | F16: =IFERROR(__xludf.DUMMYFUNCTION("SPLIT(E16, ""-"")"),"Tablet") -> Tablet | G16: =IFERROR(__xludf.DUMMYFUNCTION("""COMPUTED_VALUE"""),"Estándar") -> Estándar | H16: =IFERROR(__xludf.DUMMYFUNCTION("""COMPUTED_VALUE"""),"4GB") -> 4GB | I16: 2168.25 | J16: 3 | K16: 6504.75 | L16: Fernando Marquez Almaraz | M16: benitezcarlota@yahoo.com | N16: 1d366307-d6bd-4e44-b202-bab1ce141dbd
A17: 45574 | B17: =TEXT(A17,"mmmm") -> October | C17: bogotá | D17: =PROPER(TRIM(C17)) -> Bogotá | E17: Auriculares-Bluetooth-16GB | F17: =IFERROR(__xludf.DUMMYFUNCTION("SPLIT(E17, ""-"")"),"Auriculares") -> Auriculares | G17: =IFERROR(__xludf.DUMMYFUNCTION("""COMPUTED_VALUE"""),"Bluetooth") -> Bluetooth | H17: =IFERROR(__xludf.DUMMYFUNCTION("""COMPUTED_VALUE"""),"16GB") -> 16GB | I17: 120.46 | J17: 1 | K17: 120.46 | L17: Indira Guadalupe Montez Alcaraz | M17: brivera@club.com | N17: a076e80e-95f4-4b8d-8e0e-af032fd3e7e3
A18: 45574 | B18: =TEXT(A18,"mmmm") -> October | C18: CALI | D18: =PROPER(TRIM(C18)) -> Cali | E18: Tablet-Mini-32GB | F18: =IFERROR(__xludf.DUMMYFUNCTION("SPLIT(E18, ""-"")"),"Tablet") -> Tablet | G18: =IFERROR(__xludf.DUMMYFUNCTION("""COMPUTED_VALUE"""),"Mini") -> Mini | H18: =IFERROR(__xludf.DUMMYFUNCTION("""COMPUTED_VALUE"""),"32GB") -> 32GB | I18: 525.13 | J18: 2 | K18: 1050.26 | L18: Ing. María José Noriega | M18: victor38@industrias.com | N18: 55a4140a-ad3c-4b67-9d33-7eb275fe9440
A19: 45575 | B19: =TEXT(A19,"mmmm") -> October | C19: bogotá | D19: =PROPER(TRIM(C19)) -> Bogotá | E19: Laptop-Oficina-16GB | F19: =IFERROR(__xludf.DUMMYFUNCTION("SPLIT(E19, ""-"")"),"Laptop") -> Laptop | G19: =IFERROR(__xludf.DUMMYFUNCTION("""COMPUTED_VALUE"""),"Oficina") -> Oficina | H19: =IFERROR(__xludf.DUMMYFUNCTION("""COMPUTED_VALUE"""),"16GB") -> 16GB | I19: 278.37 | J19: 3 | K19: 835.11 | L19: Mtro. César Verduzco | M19: maria-elena87@proyectos.biz | N19: af1640cb-8d21-4be4-a497-cf19ebe3fa3e
A20: 45575 | B20: =TEXT(A20,"mmmm") -> October | C20: Medellín | D20: =PROPER(TRIM(C20)) -> Medellín | E20: Teléfono-Gama media-32GB | F20: =IFERROR(__xludf.DUMMYFUNCTION("SPLIT(E20, ""-"")"),"Teléfono") -> Teléfono | G20: =IFERROR(__xludf.DUMMYFUNCTION("""COMPUTED_VALUE"""),"Gama media") -> Gama media | H20: =IFERROR(__xludf.DUMMYFUNCTION("""COMPUTED_VALUE"""),"32GB") -> 32GB | I20: 157.57 | J20: 2 | K20: 315.14 | L20: Ernesto Rendon | M20: nadame@hotmail.com | N20: 7c7c5e94-04af-466b-bbd2-9ba60b16b6cc
A21: 45575 | B21: =TEXT(A21,"mmmm") -> October | C21: TULUM | D21: =PROPER(TRIM(C21)) -> Tulum | E21: Laptop-Gaming-32GB | F21: =IFERROR(__xludf.DUMMYFUNCTION("SPLIT(E21, ""-"")"),"Laptop") -> Laptop | G21: =IFERROR(__xludf.DUMMYFUNCTION("""COMPUTED_VALUE"""),"Gaming") -> Gaming | H21: =IFERROR(__xludf.DUMMYFUNCTION("""COMPUTED_VALUE"""),"32GB") -> 32GB | I21: 981.62 | J21: 5 | K21: 4908.1 | L21: Julio César Fernando Cordero | M21: fmontalvo@gmail.com | N21: fd56654c-43c9-4016-8183-cbdf6b382ba6
A22: 45575 | B22: =TEXT(A22,"mmmm") -> October | C22: Ciudad de Mexico | D22: =PROPER(TRIM(C22)) -> Ciudad De Mexico | E22: Tablet-Mini-8GB | F22: =IFERROR(__xludf.DUMMYFUNCTION("SPLIT(E22, ""-"")"),"Tablet") -> Tablet | G22: =IFERROR(__xludf.DUMMYFUNCTION("""COMPUTED_VALUE"""),"Mini") -> Mini | H22: =IFERROR(__xludf.DUMMYFUNCTION("""COMPUTED_VALUE"""),"8GB") -> 8GB | I22: 646.22 | J22: 2 | K22: 1292.44 | L22: Augusto Oswaldo Arce Guardado | M22: marcos44@yahoo.com | N22: b510688e-fa24-4654-b955-0b6adeee039e
A23: 45575 | B23: =TEXT(A23,"mmmm") -> October | C23: Guadalajara | D23: =PROPER(TRIM(C23)) -> Guadalajara | E23: Tablet-Pro-4GB | F23: =IFERROR(__xludf.DUMMYFUNCTION("SPLIT(E23, ""-"")"),"Tablet") -> Tablet | G23: =IFERROR(__xludf.DUMMYFUNCTION("""COMPUTED_VALUE"""),"Pro") -> Pro | H23: =IFERROR(__xludf.DUMMYFUNCTION("""COMPUTED_VALUE"""),"4GB") -> 4GB | I23: 1848.98 | J23: 3 | K23: 5546.94 | L23: Maximiliano Omar Brito Vega | M23: julio50@hotmail.com | N23: 99bc21fb-dcd1-48e4-be06-9bd0b762b73e
A24: 45575 | B24: =TEXT(A24,"mmmm") -> October | C24: CALI | D24: =PROPER(TRIM(C24)) -> Cali | E24: Teléfono-Gama alta-32GB | F24: =IFERROR(__xludf.DUMMYFUNCTION("SPLIT(E24, ""-"")"),"Teléfono") -> Teléfono | G24: =IFERROR(__xludf.DUMMYFUNCTION("""COMPUTED_VALUE"""),"Gama alta") -> Gama alta | H24: =IFERROR(__xludf.DUMMYFUNCTION("""COMPUTED_VALUE"""),"32GB") -> 32GB | I24: 1420.28 | J24: 4 | K24: 5681.12 | L24: Alejandra Najera Miramontes | M24: umadrigal@despacho.biz | N24: 38daf333-0f89-435f-9b2d-a6d639ff33df
A25: 45576 | B25: =TEXT(A25,"mmmm") -> October | C25: Medellín | D25: =PROPER(TRIM(C25)) -> Medellín | E25: Auriculares-Bluetooth-16GB | F25: =IFERROR(__xludf.DUMMYFUNCTION("SPLIT(E25, ""-"")"),"Auriculares") -> Auriculares | G25: =IFERROR(__xludf.DUMMYFUNCTION("""COMPUTED_VALUE"""),"Bluetooth") -> Bluetooth | H25: =IFERROR(__xludf.DUMMYFUNCTION("""COMPUTED_VALUE"""),"16GB") -> 16GB | I25: 2208.12 | J25: 2 | K25: 4416.24 | L25: Benjamín Marcela Lucero | M25: cresporaquel@yahoo.com | N25: cc9f2851-c332-405f-a3fb-1abae821a706
A26: 45576 | B26: =TEXT(A26,"mmmm") -> October | C26: Medellín | D26: =PROPER(TRIM(C26)) -> Medellín | E26: Tablet-Estándar-16GB | F26: =IFERROR(__xludf.DUMMYFUNCTION("SPLIT(E26, ""-"")"),"Tablet") -> Tablet | G26: =IFERROR(__xludf.DUMMYFUNCTION("""COMPUTED_VALUE"""),"Estándar") -> Estándar | H26: =IFERROR(__xludf.DUMMYFUNCTION("""COMPUTED_VALUE"""),"16GB") -> 16GB | I26: 591.94 | J26: 2 | K26: 1183.88 | L26: Eloy Godoy del Río | M26: kveliz@gmail.com | N26: 7ac1b8fd-c88f-4033-9061-4a7613449273
A27: 45576 | B27: =TEXT(A27,"mmmm") -> October | C27: monterrey | D27: =PROPER(TRIM(C27)) -> Monterrey | E27: Auriculares-Bluetooth-4GB | F27: =IFERROR(__xludf.DUMMYFUNCTION("SPLIT(E27, ""-"")"),"Auriculares") -> Auriculares | G27: =IFERROR(__xludf.DUMMYFUNCTION("""COMPUTED_VALUE"""),"Bluetooth") -> Bluetooth | H27: =IFERROR(__xludf.DUMMYFUNCTION("""COMPUTED_VALUE"""),"4GB") -> 4GB | I27: 1429.89 | J27: 4 | K27: 5719.56 | L27: Luis Manuel Ilse Apodaca | M27: ilse56@tapia-zavala.com | N27: a1cb1e10-0e31-479a-b8bb-5dc909b32b66
A28: 45576 | B28: =TEXT(A28,"mmmm") -> October | C28: Medellín | D28: =PROPER(TRIM(C28)) -> Medellín | E28: Auriculares-Con cable-8GB | F28: =IFERROR(__xludf.DUMMYFUNCTION("SPLIT(E28, ""-"")"),"Auriculares") -> Auriculares | G28: =IFERROR(__xludf.DUMMYFUNCTION("""COMPUTED_VALUE"""),"Con cable") -> Con cable | H28: =IFERROR(__xludf.DUMMYFUNCTION("""COMPUTED_VALUE"""),"8GB") -> 8GB | I28: 2085.29 | J28: 1 | K28: 2085.29 | L28: Eugenio Juana Orta Chapa | M28: marco-antoniorosado@grupo.org | N28: 3786d3a2-e035-4239-845a-3dce8eca0b61
A29: 45576 | B29: =TEXT(A29,"mmmm") -> October | C29: GUADALAJARA | D29: =PROPER(TRIM(C29)) -> Guadalajara | E29: Teléfono-Gama baja-16GB | F29: =IFERROR(__xludf.DUMMYFUNCTION("SPLIT(E29, ""-"")"),"Teléfono") -> Teléfono | G29: =IFERROR(__xludf.DUMMYFUNCTION("""COMPUTED_VALUE"""),"Gama baja") -> Gama baja | H29: =IFERROR(__xludf.DUMMYFUNCTION("""COMPUTED_VALUE"""),"16GB") -> 16GB | I29: 724.28 | J29: 3 | K29: 2172.84 | L29: Octavio Briseño Corrales | M29: antoniohernandez@gmail.com | N29: 06092c99-a04c-49aa-b1e2-81711e255109
A30: 45576 | B30: =TEXT(A30,"mmmm") -> October | C30: CALI | D30: =PROPER(TRIM(C30)) -> Cali | E30: Teléfono-Gama alta-8GB | F30: =IFERROR(__xludf.DUMMYFUNCTION("SPLIT(E30, ""-"")"),"Teléfono") -> Teléfono | G30: =IFERROR(__xludf.DUMMYFUNCTION("""COMPUTED_VALUE"""),"Gama alta") -> Gama alta | H30: =IFERROR(__xludf.DUMMYFUNCTION("""COMPUTED_VALUE"""),"8GB") -> 8GB | I30: 1859.58 | J30: 3 | K30: 5578.74 | L30: Patricio Puga | M30: maytecasares@yahoo.com | N30: 428f89ef-5eb4-469e-b29a-14fcef36e9d3
A31: 45576 | B31: =TEXT(A31,"mmmm") -> October | C31: Medellín | D31: =PROPER(TRIM(C31)) -> Medellín | E31: Teléfono-Gama media-8GB | F31: =IFERROR(__xludf.DUMMYFUNCTION("SPLIT(E31, ""-"")"),"Teléfono") -> Teléfono | G31: =IFERROR(__xludf.DUMMYFUNCTION("""COMPUTED_VALUE"""),"Gama media") -> Gama media | H31: =IFERROR(__xludf.DUMMYFUNCTION("""COMPUTED_VALUE"""),"8GB") -> 8GB | I31: 218.17 | J31: 4 | K31: 872.68 | L31: Antonio Adriana Razo | M31: reyesespartaco@hotmail.com | N31: c08f9ba9-0e32-4277-937a-eae40b912ab0
A32: 45576 | B32: =TEXT(A32,"mmmm") -> October | C32: Ciudad de Mexico | D32: =PROPER(TRIM(C32)) -> Ciudad De Mexico | E32: Tablet-Pro-4GB | F32: =IFERROR(__xludf.DUMMYFUNCTION("SPLIT(E32, ""-"")"),"Tablet") -> Tablet | G32: =IFERROR(__xludf.DUMMYFUNCTION("""COMPUTED_VALUE"""),"Pro") -> Pro | H32: =IFERROR(__xludf.DUMMYFUNCTION("""COMPUTED_VALUE"""),"4GB") -> 4GB | I32: 1375.85 | J32: 1 | K32: 1375.85 | L32: Isabel Maya | M32: tozuna@yahoo.com | N32: e8070b1a-de24-4296-b9ca-c4d62784eb47
A33: 45576 | B33: =TEXT(A33,"mmmm") -> October | C33: Guadalajara | D33: =PROPER(TRIM(C33)) -> Guadalajara | E33: Tablet-Pro-8GB | F33: =IFERROR(__xludf.DUMMYFUNCTION("SPLIT(E33, ""-"")"),"Tablet") -> Tablet | G33: =IFERROR(__xludf.DUMMYFUNCTION("""COMPUTED_VALUE"""),"Pro") -> Pro | H33: =IFERROR(__xludf.DUMMYFUNCTION("""COMPUTED_VALUE"""),"8GB") -> 8GB | I33: 421.59 | J33: 2 | K33: 843.18 | L33: Lic. Carlota Ontiveros | M33: francisco-javierzamudio@gmail.com | N33: 19a6e9f7-0a45-4879-ab17-df6979e1e612
A34: 45576 | B34: =TEXT(A34,"mmmm") -> October | C34: monterrey | D34: =PROPER(TRIM(C34)) -> Monterrey | E34: Tablet-Mini-32GB | F34: =IFERROR(__xludf.DUMMYFUNCTION("SPLIT(E34, ""-"")"),"Tablet") -> Tablet | G34: =IFERROR(__xludf.DUMMYFUNCTION("""COMPUTED_VALUE"""),"Mini") -> Mini | H34: =IFERROR(__xludf.DUMMYFUNCTION("""COMPUTED_VALUE"""),"32GB") -> 32GB | I34: 2288.18 | J34: 1 | K34: 2288.18 | L34: Itzel Puente Téllez | M34: emontalvo@angulo.info | N34: e1d56019-1e10-4a1a-9dff-bff7048987d6
A35: 45576 | B35: =TEXT(A35,"mmmm") -> October | C35: monterrey | D35: =PROPER(TRIM(C35)) -> Monterrey | E35: Auriculares-Con cable-16GB | F35: =IFERROR(__xludf.DUMMYFUNCTION("SPLIT(E35, ""-"")"),"Auriculares") -> Auriculares | G35: =IFERROR(__xludf.DUMMYFUNCTION("""COMPUTED_VALUE"""),"Con cable") -> Con cable | H35: =IFERROR(__xludf.DUMMYFUNCTION("""COMPUTED_VALUE"""),"16GB") -> 16GB | I35: 1699.32 | J35: 4 | K35: 6797.28 | L35: Daniela Uribe | M35: qcolon@laureano-solorzano.net | N35: a1278508-c2d2-4e1a-9ab3-cd5dcc25c9cf
A36: 45576 | B36: =TEXT(A36,"mmmm") -> October | C36: CALI | D36: =PROPER(TRIM(C36)) -> Cali | E36: Tablet-Mini-32GB | F36: =IFERROR(__xludf.DUMMYFUNCTION("SPLIT(E36, ""-"")"),"Tablet") -> Tablet | G36: =IFERROR(__xludf.DUMMYFUNCTION("""COMPUTED_VALUE"""),"Mini") -> Mini | H36: =IFERROR(__xludf.DUMMYFUNCTION("""COMPUTED_VALUE"""),"32GB") -> 32GB | I36: 1578.34 | J36: 3 | K36: 4735.02 | L36: Gustavo Berta Aragon | M36: del-riojuan@velasco.com | N36: afc92f17-61fe-4e4e-84c2-09515ccc8e07
A37: 45577 | B37: =TEXT(A37,"mmmm") -> October | C37: bogotá | D37: =PROPER(TRIM(C37)) -> Bogotá | E37: Teléfono-Gama alta-16GB | F37: =IFERROR(__xludf.DUMMYFUNCTION("SPLIT(E37, ""-"")"),"Teléfono") -> Teléfono | G37: =IFERROR(__xludf.DUMMYFUNCTION("""COMPUTED_VALUE"""),"Gama alta") -> Gama alta | H37: =IFERROR(__xludf.DUMMYFUNCTION("""COMPUTED_VALUE"""),"16GB ") -> 16GB | I37: 1445.1 | J37: 4 | K37: 5780.4 | L37: Lorenzo Wendolin Méndez Gollum | M37: ffuentes@ochoa-molina.com | N37: 116022d7-56fc-4596-aeba-30c58ab21dbf
A38: 45577 | B38: =TEXT(A38,"mmmm") -> October | C38: Guadalajara | D38: =PROPER(TRIM(C38)) -> Guadalajara | E38: Auriculares-Bluetooth-4GB | F38: =IFERROR(__xludf.DUMMYFUNCTION("SPLIT(E38, ""-"")"),"Auriculares") -> Auriculares | G38: =IFERROR(__xludf.DUMMYFUNCTION("""COMPUTED_VALUE"""),"Bluetooth") -> Bluetooth | H38: =IFERROR(__xludf.DUMMYFUNCTION("""COMPUTED_VALUE"""),"4GB") -> 4GB | I38: 1065.52 | J38: 2 | K38: 2131.04 | L38: Serafín Samuel Tamayo Baez | M38: bruno78@vega.org | N38: c196a64f-ac47-4c79-b416-d0807432cfa3
A39: 45577 | B39: =TEXT(A39,"mmmm") -> October | C39: Ciudad de Mexico | D39: =PROPER(TRIM(C39)) -> Ciudad De Mexico | E39: Laptop-Gaming-8GB | F39: =IFERROR(__xludf.DUMMYFUNCTION("SPLIT(E39, ""-"")"),"Laptop") -> Laptop | G39: =IFERROR(__xludf.DUMMYFUNCTION("""COMPUTED_VALUE"""),"Gaming") -> Gaming | H39: =IFERROR(__xludf.DUMMYFUNCTION("""COMPUTED_VALUE"""),"8GB") -> 8GB | I39: 2095.66 | J39: 5 | K39: 10478.3 | L39: Irene Domínguez | M39: estherpedroza@rojas-moya.info | N39: 2ad918fa-d68e-42ea-926c-414454fd8220
A40: 45577 | B40: =TEXT(A40,"mmmm") -> October | C40: Guadalajara | D40: =PROPER(TRIM(C40)) -> Guadalajara | E40: Tablet-Estándar-16GB | F40: =IFERROR(__xludf.DUMMYFUNCTION("SPLIT(E40, ""-"")"),"Tablet") -> Tablet | G40: =IFERROR(__xludf.DUMMYFUNCTION("""COMPUTED_VALUE"""),"Estándar") -> Estándar | H40: =IFERROR(__xludf.DUMMYFUNCTION("""COMPUTED_VALUE"""),"16GB") -> 16GB | I40: 2215.63 | J40: 3 | K40: 6646.89 | L40: María Cristina Valdivia Mondragon | M40: porfirio68@corporacin.biz | N40: 9fc06fba-9376-4e96-97f1-0aeca2f00a87
...

Sheet Análisis
A1: Métricas | B1: Respuesta
A2: Ventas totales del trimestre | B2: =SUM(Datos_Limpios!K2:K754) -> 2944620.6
A3: Venta promedio por transacción | B3: =AVERAGE(Datos_Limpios!K2:K754) -> 3910.5187
A4: Número total de transacciones | B4: =COUNT(Datos_Limpios!J2:J754) -> 753
A5: Producto más vendido (por cantidad) | B5: Tablet
A6: Ciudad con las mayores ventas totales | B6: Monterrey
A7: Mes con los mejores resultados | B7: Octubre
A8: Precio promedio por categoría de producto | B8: Auriculares = 1256.64 Laptop = 1311.06 Tablet = 1210.01 Teléfono =1200.89

Sheet Visualizaciones
A1: Ciudad | B1: Ventas totales | C1: {={A1:B1; SORT(A2:B1000, 2, FALSE)}} -> Ciudad | D1: Ventas totales | G1: Mes | H1: Ventas totales
A2: {=UNIQUE(Datos_Limpios!D2:D1000)} -> Monterrey | B2: =SUMIF(Datos_Limpios!D:D, A2, Datos_Limpios!K:K) -> 541137.36 | C2: Monterrey | D2: 541137.36 | G2: {=UNIQUE(Datos_Limpios!B2:B1000)} -> October | H2: =SUMIF(Datos_Limpios!B:B, G2, Datos_Limpios!K:K) -> 1006043.7
A3: Bogotá | B3: =SUMIF(Datos_Limpios!D:D, A3, Datos_Limpios!K:K) -> 461010.68 | C3: Ciudad De Mexico | D3: 517689.63 | G3: November | H3: =SUMIF(Datos_Limpios!B:B, G3, Datos_Limpios!K:K) -> 1027372.5
A4: Ciudad De Mexico | B4: =SUMIF(Datos_Limpios!D:D, A4, Datos_Limpios!K:K) -> 517689.63 | C4: Guadalajara | D4: 492790.52 | G4: December | H4: =SUMIF(Datos_Limpios!B:B, G4, Datos_Limpios!K:K) -> 911204.5
A5: Medellín | B5: =SUMIF(Datos_Limpios!D:D, A5, Datos_Limpios!K:K) -> 402243.58 | C5: Cali | D5: 475354.11
A6: Guadalajara | B6: =SUMIF(Datos_Limpios!D:D, A6, Datos_Limpios!K:K) -> 492790.52 | C6: Bogotá | D6: 461010.68
A7: Cali | B7: =SUMIF(Datos_Limpios!D:D, A7, Datos_Limpios!K:K) -> 475354.11 | C7: Medellín | D7: 402243.58
A8: Tulum | B8: =SUMIF(Datos_Limpios!D:D, A8, Datos_Limpios!K:K) -> 54394.73 | C8: Tulum | D8: 54394.73
G29: 📊 Insights clave:
G31: • Ciudad líder: Monterrey
G32: • Mayor venta: Noviembre
G33: • Tendencia: crecimiento y caída en diciembre

Sheet Informe_Ejecutivo
A1: Resumen ejecutivo
A2: Categoría | B2: Respuesta
A3: 1. Limpieza
A4: Cantidad de datos duplicados | B4: No se encontraron filas duplicadas
A5: Cantidad de filas con valor nulo en la columna `Precio unitario` y `Monto total` | B5: Se esncontraron 6 filas en la columnade Monto total vacias las cuales corresponden a las filas: 56, 104, 375, 428, 497 y 511. Y se encontraron 10 filas vacias en la columna de precio unitario las culaes son: 44, 55, 92, 115, 183, 318, 322, 429, 446 y 539
A6: 2. Hallazgos principales
A7: Producto más vendido por cantidad | B7: Tablet
A8: Ciudad con mayor volumen de ventas totales | B8: Monterrey
A9: Precio promedio por categoría de producto | B9: Auriculares = 1256.64 Laptop = 1311.06 Tablet = 1210.01 Teléfono =1200.89
A10: Recomendación | B10: Las ventas se concentran en Monterrey, siendo la ciudad con mayor desempeño durante el trimestre. Se recomienda fortalecer las estrategias comerciales en esta ciudad, como promociones y fidelización de clientes, para maximizar ingresos, mientras se analizan oportunidades de crecimiento en ciudades con menor rendimiento como Tulum. También, Las ventas alcanzan su punto máximo en noviembre y disminuyen en diciembre. Se recomienda reforzar estrategias comerciales al cierre del trimestre para evitar la caída en ventas
A11: 3. Metodología de limpieza
A12: Problemas encontrados en los datos originales. | B12: Durante el proceso de preparación del dataset, se identificaron varios problemas de calidad que dificultaban el análisis adecuado de la información. A continuación, se describen las acciones realizadas: Columna “Fecha de venta”: Los datos se encontraban en un único formato que no facilitaba el análisis temporal. Se transformaron y organizaron para permitir el estudio del comportamiento de las ventas a lo largo del tiempo, incluyendo la creación de una columna adicional de mes. Columna “Ciudad”: Se detectaron inconsistencias en el formato de los nombres, así como espacios innecesarios. Se aplicaron funciones de limpieza para estandarizar los textos (uso de mayúsculas/minúsculas y eliminación de espacios), generando una columna de “Ciudad corregida”. Columna “Producto”: Contenía múltiples atributos en una sola celda, lo que dificultaba su análisis. Se procedió a dividir esta información en columnas independientes (categoría, tipo y especificaciones) para mejorar su usabilidad. Columnas numéricas: Los valores no contaban con un formato adecuado. Se aplicó formato de moneda para facilitar la lectura e interpretación de los datos.
A13: 4. Limitaciones
A14: Información adicional requerida (si aplica) | B14: Tuve que estudiar temas no vistos en el sprint par apoder dar ciertas coluciones como usar datos de una hoja en otra
